Workbook

Sheet SUMMARY
B2: DEVELOPMENT APPRAISAL — SUMMARY
B3: [Enter scheme address here]
B5: SCHEME | F5: SCENARIO COMPARISON
B6: Total units | D6: ='1. Unit Import'!F40 -> 12 | F6: Scenario | G6: Net profit | H6: Profit on GDV | I6: Investor ROI | J6: Months
B7: Total NIA (sqft) | D7: ='1. Unit Import'!F41 -> 10344.108 | F7: S1 — Immediate sale at PC | G7: ='5. Scenarios'!F9 -> 775845.16 | H7: ='5. Scenarios'!F11 -> 0.12417042 | I7: ='5. Scenarios'!F15 -> 0.55417512 | J7: ='5. Scenarios'!F16 -> 15
B8: GDV | D8: ='1. Unit Import'!F42 -> 6248228.7 | F8: S2 — Delayed sales (dev loan) | G8: ='5. Scenarios'!F36 -> 702623.96 | H8: =IF('5. Scenarios'!F5=0,0,'5. Scenarios'!F36/'5. Scenarios'!F5) -> 0.1124517 | I8: ='5. Scenarios'!F38 -> 0.50187425 | J8: ='5. Scenarios'!F39 -> 21
B9: Average £psf | D9: ='1. Unit Import'!F43 -> 604.03746 | F9: S3 — Refinance & rent (pa cashflow) | G9: ='5. Scenarios'!F50 -> -29574.175 | H9: =IF('5. Scenarios'!F5=0,0,'5. Scenarios'!F54/'5. Scenarios'!F5) -> 0.12417042 | I9: ='5. Scenarios'!F53 -> -0.020372823 | J9: "hold"
B10: Programme (months to PC) | D10: ='2. Inputs'!E14 -> 15 | F10: S4 — Refinance then delayed sales | G10: ='5. Scenarios'!F72 -> 687155.1 | H10: =IF('5. Scenarios'!F5=0,0,'5. Scenarios'!F72/'5. Scenarios'!F5) -> 0.10997598 | I10: ='5. Scenarios'!F75 -> 0.49082507 | J10: ='5. Scenarios'!F39 -> 21
F11: S3 shows annual rental cashflow (not a one-off profit); unrealised profit stays in the asset.
B12: COSTS
B13: (A) Purchase price | D13: ='3. Dev Costs'!F8 -> 1950000 | F13: KEY ASSUMPTIONS & NOTES
B14: (B) Legals | D14: ='3. Dev Costs'!F19 -> 131250 | F14: 1. Costs spread evenly within each phase (no S-curve): legals over the legal period, professional fees over pre-construction, build costs over construction.
B15: (C) Professional fees | D15: ='3. Dev Costs'!F34 -> 150300 | F15: 2. Bridge: interest & arrangement fee rolled up from site purchase; redeemed (plus exit fee) by the first development loan drawdown at construction start.
B16: (D) Development costs | D16: ='3. Dev Costs'!F49 -> 2668180.4 | F16: 3. Development loan: fully rolled up; equity deploys first, loan funds the balance monthly. Arrangement fee estimated on the facility estimate ('2. Inputs' E29).
B17: (E) During construction | D17: ='3. Dev Costs'!F58 -> 38400 | F17: 4. SDLT is a manual input on '3. Dev Costs' - Still need to import an SDLT calculator for the actual figure.
B18: (F) Post construction | D18: ='3. Dev Costs'!F65 -> 13550 | F18: 5. Delayed-sale scenarios sell at the average unit price (GDV ÷ units); Sensitivity Grid 2 uses a straight-line paydown approximation.
B19: (G) Sales & marketing | D19: ='3. Dev Costs'!F74 -> 143723.43 | F19: 6. Scenario 3 mortgage is interest-only; rent net of void and management inputs.
B20: (H) Other | D20: ='3. Dev Costs'!F85 -> 20660 | F20: 7. Example figures throughout are placeholders based on the Richer Sounds appraisal DDC Tom emailed me.
B21: (I) Finance costs | D21: ='4. Cashflow'!C43 -> 356319.64
B22: TOTAL COSTS AFTER FINANCE | D22: ='4. Cashflow'!C44 -> 5472383.5
B24: FUNDING
B25: Equity - investor (50%) | D25: ='2. Inputs'!E36 -> 700000
B26: Equity - developer (50%) | D26: ='2. Inputs'!E37 -> 700000
B27: Bridge advance (day 1) | D27: ='2. Inputs'!E21 -> 1267500
B28: Peak development loan | D28: ='4. Cashflow'!C41 -> 4032062.9
B29: LTGDV at peak | D29: ='4. Cashflow'!C42 -> 0.64531295
B30: LTC (peak debt ÷ costs after finance) | D30: =IF('4. Cashflow'!C44=0,0,'4. Cashflow'!C41/'4. Cashflow'!C44) -> 0.73680196

Sheet 1. Unit Import
B2: 1. Unit Import — Unit Schedule
B6: No | C6: Unit Name | D6: Floor | E6: Type | F6: Sqm | G6: Sqft | H6: Sale £psf | I6: Unit GDV | J6: Build months | K6: Monthly Rent £ | L6: Notes
B7: 1 | C7: Commercial Unit | D7: G | E7: Commercial | F7: 64 | G7: =IF(F7="","",F7*10.7639) -> 688.8896 | H7: 254 | I7: =IF(OR(F7="",H7=""),"",G7*H7) -> 174977.96 | J7: 6 | K7: 1200
B8: 2 | C8: Apartment 1 | D8: 1 | E8: 2 bed | F8: 76 | G8: =IF(F8="","",F8*10.7639) -> 818.0564 | H8: 611 | I8: =IF(OR(F8="",H8=""),"",G8*H8) -> 499832.46 | J8: 10 | K8: 1650
B9: 3 | C9: Apartment 2 | D9: 1 | E9: 2 bed | F9: 70 | G9: =IF(F9="","",F9*10.7639) -> 753.473 | H9: 617 | I9: =IF(OR(F9="",H9=""),"",G9*H9) -> 464892.84 | J9: 10 | K9: 1550
B10: 4 | C10: Apartment 3 | D10: 1 | E10: 2 bed | F10: 93 | G10: =IF(F10="","",F10*10.7639) -> 1001.0427 | H10: 574 | I10: =IF(OR(F10="",H10=""),"",G10*H10) -> 574598.51 | J10: 10 | K10: 1850
B11: 5 | C11: Apartment 4 | D11: 2 | E11: 2 bed | F11: 76 | G11: =IF(F11="","",F11*10.7639) -> 818.0564 | H11: 617 | I11: =IF(OR(F11="",H11=""),"",G11*H11) -> 504740.8 | J11: 11 | K11: 1650
B12: 6 | C12: Apartment 5 | D12: 2 | E12: 2 bed | F12: 70 | G12: =IF(F12="","",F12*10.7639) -> 753.473 | H12: 630 | I12: =IF(OR(F12="",H12=""),"",G12*H12) -> 474687.99 | J12: 11 | K12: 1550
B13: 7 | C13: Apartment 6 | D13: 2 | E13: 2 bed | F13: 93 | G13: =IF(F13="","",F13*10.7639) -> 1001.0427 | H13: 584 | I13: =IF(OR(F13="",H13=""),"",G13*H13) -> 584608.94 | J13: 11 | K13: 1850
B14: 8 | C14: Apartment 7 | D14: 3 | E14: 2 bed | F14: 76 | G14: =IF(F14="","",F14*10.7639) -> 818.0564 | H14: 630 | I14: =IF(OR(F14="",H14=""),"",G14*H14) -> 515375.53 | J14: 12 | K14: 1650 | L14: new build
B15: 9 | C15: Apartment 8 | D15: 3 | E15: 2 bed | F15: 70 | G15: =IF(F15="","",F15*10.7639) -> 753.473 | H15: 644 | I15: =IF(OR(F15="",H15=""),"",G15*H15) -> 485236.61 | J15: 12 | K15: 1550 | L15: new build
B16: 10 | C16: Apartment 9 | D16: 3 | E16: 2 bed | F16: 93 | G16: =IF(F16="","",F16*10.7639) -> 1001.0427 | H16: 594 | I16: =IF(OR(F16="",H16=""),"",G16*H16) -> 594619.36 | J16: 12 | K16: 1850 | L16: new build
B17: 11 | C17: Apartment 10 | D17: 4 | E17: 2 bed | F17: 87 | G17: =IF(F17="","",F17*10.7639) -> 936.4593 | H17: 694 | I17: =IF(OR(F17="",H17=""),"",G17*H17) -> 649902.75 | J17: 12 | K17: 1800 | L17: new build
B18: 12 | C18: Apartment 11 | D18: 4 | E18: 2 bed | F18: 93 | G18: =IF(F18="","",F18*10.7639) -> 1001.0427 | H18: 724 | I18: =IF(OR(F18="",H18=""),"",G18*H18) -> 724754.91 | J18: 12 | K18: 1850 | L18: new build
G19: =IF(F19="","",F19*10.7639) | I19: =IF(OR(F19="",H19=""),"",G19*H19)
G20: =IF(F20="","",F20*10.7639) | I20: =IF(OR(F20="",H20=""),"",G20*H20)
G21: =IF(F21="","",F21*10.7639) | I21: =IF(OR(F21="",H21=""),"",G21*H21)
G22: =IF(F22="","",F22*10.7639) | I22: =IF(OR(F22="",H22=""),"",G22*H22)
G23: =IF(F23="","",F23*10.7639) | I23: =IF(OR(F23="",H23=""),"",G23*H23)
G24: =IF(F24="","",F24*10.7639) | I24: =IF(OR(F24="",H24=""),"",G24*H24)
G25: =IF(F25="","",F25*10.7639) | I25: =IF(OR(F25="",H25=""),"",G25*H25)
G26: =IF(F26="","",F26*10.7639) | I26: =IF(OR(F26="",H26=""),"",G26*H26)
G27: =IF(F27="","",F27*10.7639) | I27: =IF(OR(F27="",H27=""),"",G27*H27)
G28: =IF(F28="","",F28*10.7639) | I28: =IF(OR(F28="",H28=""),"",G28*H28)
G29: =IF(F29="","",F29*10.7639) | I29: =IF(OR(F29="",H29=""),"",G29*H29)
G30: =IF(F30="","",F30*10.7639) | I30: =IF(OR(F30="",H30=""),"",G30*H30)
... G36: =IF(F36="","",F36*10.7639) | I36: =IF(OR(F36="",H36=""),"",G36*H36)
C38: TOTAL | F38: =SUM(F7:F36) -> 961 | G38: =SUM(G7:G36) -> 10344.108 | I38: =SUM(I7:I36) -> 6248228.7 | K38: =SUM(K7:K36) -> 20000
C40: Total units | F40: =COUNTA(C7:C36) -> 12
C41: Total NIA (sqft) | F41: =G38 -> 10344.108
C42: GDV TOTAL | F42: =I38 -> 6248228.7
C43: Average £psf | F43: =IF(G38=0,0,I38/G38) -> 604.03746
C44: Full development build time (months) = MAX build months | F44: =MAX(J7:J36) -> 12
C45: Total monthly rent | F45: =K38 -> 20000
C46: Gross annual rent | F46: =K38*12 -> 240000

Sheet 2. Inputs
B2: 2. Inputs — Programme & Finance Parameters | G2: BLUE/yellow cells = your inputs. Black = calculated. Green = linked from another sheet.
B4: (A) SITE & PURCHASE
C5: Purchase price | E5: 1950000
C6: Purchase date (Month 1) | E6: 46235
C7: GIA (gross internal area, sqft) | E7: 11586 | G7: used for build £psf metric
B9: (B) PROGRAMME / BUILD TIME
C10: Legal / purchase period (months) | E10: 2 | G10: legals spread over these months
C11: Pre-construction period (months) | E11: 3 | G11: bridge phase: purchase → start on site
C12: Construction period (months) | E12: ='1. Unit Import'!F44 -> 12 | G12: equals longest unit build time on '1. Unit Import'
C13: Construction start month | E13: =E11+1 -> 4
C14: Practical completion (PC) month | E14: =E11+E12 -> 15
B16: (C) BRIDGING LOAN — site purchase, interest rolled up
C17: LTV on purchase price | E17: 0.65
C18: Interest rate (pa) | E18: 0.1
C19: Arrangement fee (rolled) | E19: 0.02
C20: Exit fee | E20: 0.01
C21: Bridge advance (day 1) | E21: =E5*E17 -> 1267500 | G21: cash received at purchase
C22: Est. redemption at dev-loan start | E22: =E21*(1+E19)*(1+E18/12)^E11*(1+E20) -> 1338695.8 | G22: principal + rolled fee & interest + exit fee
B24: (D) DEVELOPMENT LOAN — rolled up, repaid at exit
C25: Interest rate (pa) | E25: 0.085
C26: Arrangement fee (rolled) | E26: 0.015
C27: Exit fee | E27: 0.01
C28: Max LTGDV covenant | E28: 0.65
C29: Est. facility required | E29: ='3. Dev Costs'!F87-E33-E21+E22 -> 3787259.6 | G29: costs − equity − bridge advance + bridge redemption
C30: Arrangement fee £ (rolled at first draw) | E30: =E26*E29 -> 56808.894
B32: (E) SPV & EQUITY — 50/50 with external investor
C33: Total equity injected | E33: 1400000
C34: Investor share | E34: 0.5
C35: Developer share | E35: =1-E34 -> 0.5
C36: Investor equity | E36: =E33*E34 -> 700000
C37: Developer equity | E37: =E33*E35 -> 700000
B39: (F) SALES ASSUMPTIONS
C40: Sales agent fee (% of price) | E40: 0.015
C41: Legal cost per unit sale | E41: 750
C42: Sales velocity (units per month) | E42: 2 | G42: delayed-sale scenarios
C43: Price adjustment vs GDV | E43: 0 | G43: 0% = sell at GDV; scenario lever
B45: (G) REFINANCE / EXIT — exit bridge or commercial mortgage
C46: Refinance LTV (% of GDV) | E46: 0.65
C47: Refinance interest rate (pa) | E47: 0.055
C48: Arrangement fee | E48: 0.01
...

Sheet 3. Dev Costs
B2: 3. Development Costs (structure per Richer Sounds appraisal)
B3: BLUE = input amounts. Column D = rate/% helpers (blue where input). Amounts in column F feed the monthly cashflow.
B6: (A) PURCHASE
C7: Purchase price | F7: ='2. Inputs'!E5 -> 1950000
C8: TOTAL | F8: =F7 -> 1950000
B10: (B) LEGALS & ACQUISITION
B11: B01 | C11: Purchase legals (solicitor) | F11: 7500
B12: B02 | C12: Searches, title indemnity & surveys | F12: 2500
B13: B03 | C13: Valuation report | F13: 1500
B14: B04 | C14: Stamp Duty (SDLT) | F14: 87000 | G14: enter from SDLT calculator (incl. any VAT on price)
B15: B05 | C15: Sourcing fee | D15: 0.01 | F15: =D15*'2. Inputs'!E5 -> 19500
B16: B06 | C16: Agent commission | D16: 0.005 | F16: =D16*'2. Inputs'!E5 -> 9750
B17: B07 | C17: Legal contingency | F17: 1500
B18: B08 | C18: Other | F18: 2000
C19: TOTAL | F19: =SUM(F11:F18) -> 131250
B21: (C) PROFESSIONAL FEES (pre-construction)
B22: C01 | C22: Architect fees | F22: 42500
B23: C02 | C23: Planning consultant | F23: 10700
B24: C03 | C24: Structural engineer | F24: 15650
B25: C04 | C25: Building control | F25: 7300
B26: C05 | C26: M&E engineer | F26: 10000
B27: C06 | C27: Surveys (measured / asbestos / noise / drainage / roof) | F27: 13000
B28: C07 | C28: Fire engineer | F28: 15650
B29: C08 | C29: Principal designer role | F29: 3000
B30: C09 | C30: Party wall surveyor | F30: 5000
B31: C10 | C31: Building insurance (pre-construction) | F31: 7500
B32: C11 | C32: Planning conditions & other reports | F32: 10000
B33: C12 | C33: Other | F33: 10000
C34: TOTAL | F34: =SUM(F22:F33) -> 150300
B36: (D) DEVELOPMENT / CONSTRUCTION COSTS
B37: D01 | C37: Build cost (main contract) | D37: =IF('2. Inputs'!E7=0,0,F37/'2. Inputs'!E7) -> 198.95555 | F37: 2305099 | G37: £psf shown in D
B38: D02 | C38: Utilities (connections etc.) | F38: 40000
B39: D03 | C39: Employer's agent | F39: 60000
B40: D04 | C40: Project management | F40: 20000
B41: D05 | C41: Quantity surveyor | F41: 33000
B42: D06 | C42: Health & safety consultant | F42: 2850
B43: D07 | C43: Interior designer | F43: 20000
B44: D08 | C44: Contingency (% of build) | D44: 0.05 | F44: =D44*F37 -> 115254.95
B45: D09 | C45: Demolition & site clearance (% of build) | D45: 0.015 | F45: =D45*F37 -> 34576.485
B46: D10 | C46: 10-yr structural warranty (per unit) | D46: 1200 | F46: =D46*'1. Unit Import'!F40 -> 14400
...

Sheet 4. Cashflow
B2: 4. Monthly Cashflow & Finance Engine
B3: Costs spread evenly across phases. Bridge rolls up from purchase, redeemed by the development loan at construction start; dev loan rolls up to practical completion (PC). Repayment happens in the Scenarios sheet.
B4: Month | E4: 1 | F4: 2 | G4: 3 | H4: 4 | I4: 5 | J4: 6 | K4: 7 | L4: 8 | M4: 9 | N4: 10 | O4: 11 | P4: 12 | Q4: 13 | R4: 14 | S4: 15 | T4: 16 | U4: 17 | V4: 18 | W4: 19 | X4: 20 | Y4: 21 | Z4: 22 | AA4: 23 | AB4: 24 | AC4: 25 | AD4: 26 | AE4: 27 | AF4: 28 | AG4: 29 | AH4: 30 | AI4: 31 | AJ4: 32 | AK4: 33 | AL4: 34 | AM4: 35 | AN4: 36 | AO4: 37 | AP4: 38 | AQ4: 39 | AR4: 40 | AS4: 41 | AT4: 42 | AU4: 43 | AV4: 44 | AW4: 45 | AX4: 46 | AY4: 47 | AZ4: 48
B5: Date | E5: =EDATE('2. Inputs'!$E$6,E4-1) -> 46235 | F5: =EDATE('2. Inputs'!$E$6,F4-1) -> 46266 | G5: =EDATE('2. Inputs'!$E$6,G4-1) -> 46296 | H5: =EDATE('2. Inputs'!$E$6,H4-1) -> 46327 | I5: =EDATE('2. Inputs'!$E$6,I4-1) -> 46357 | J5: =EDATE('2. Inputs'!$E$6,J4-1) -> 46388 | K5: =EDATE('2. Inputs'!$E$6,K4-1) -> 46419 | L5: =EDATE('2. Inputs'!$E$6,L4-1) -> 46447 | ... AZ5: =EDATE('2. Inputs'!$E$6,AZ4-1) -> 47665
B7: PROJECT COSTS
B8: (A) Purchase | C8: =SUM(E8:AZ8) -> 1950000 | E8: =IF(E$4=1,'3. Dev Costs'!$F$7,0) -> 1950000 | F8: =IF(F$4=1,'3. Dev Costs'!$F$7,0) -> 0 | G8: =IF(G$4=1,'3. Dev Costs'!$F$7,0) -> 0 | H8: =IF(H$4=1,'3. Dev Costs'!$F$7,0) -> 0 | I8: =IF(I$4=1,'3. Dev Costs'!$F$7,0) -> 0 | J8: =IF(J$4=1,'3. Dev Costs'!$F$7,0) -> 0 | K8: =IF(K$4=1,'3. Dev Costs'!$F$7,0) -> 0 | L8: =IF(L$4=1,'3. Dev Costs'!$F$7,0) -> 0 | ... AZ8: =IF(AZ$4=1,'3. Dev Costs'!$F$7,0) -> 0
B9: (B) Legals | C9: =SUM(E9:AZ9) -> 131250 | E9: =IF(E$4<='2. Inputs'!$E$10,'3. Dev Costs'!$F$19/'2. Inputs'!$E$10,0) -> 65625 | F9: =IF(F$4<='2. Inputs'!$E$10,'3. Dev Costs'!$F$19/'2. Inputs'!$E$10,0) -> 65625 | G9: =IF(G$4<='2. Inputs'!$E$10,'3. Dev Costs'!$F$19/'2. Inputs'!$E$10,0) -> 0 | H9: =IF(H$4<='2. Inputs'!$E$10,'3. Dev Costs'!$F$19/'2. Inputs'!$E$10,0) -> 0 | I9: =IF(I$4<='2. Inputs'!$E$10,'3. Dev Costs'!$F$19/'2. Inputs'!$E$10,0) -> 0 | J9: =IF(J$4<='2. Inputs'!$E$10,'3. Dev Costs'!$F$19/'2. Inputs'!$E$10,0) -> 0 | K9: =IF(K$4<='2. Inputs'!$E$10,'3. Dev Costs'!$F$19/'2. Inputs'!$E$10,0) -> 0 | L9: =IF(L$4<='2. Inputs'!$E$10,'3. Dev Costs'!$F$19/'2. Inputs'!$E$10,0) -> 0 | ... AZ9: =IF(AZ$4<='2. Inputs'!$E$10,'3. Dev Costs'!$F$19/'2. Inputs'!$E$10,0) -> 0
B10: (C) Professional fees | C10: =SUM(E10:AZ10) -> 150300 | E10: =IF(E$4<='2. Inputs'!$E$11,'3. Dev Costs'!$F$34/'2. Inputs'!$E$11,0) -> 50100 | F10: =IF(F$4<='2. Inputs'!$E$11,'3. Dev Costs'!$F$34/'2. Inputs'!$E$11,0) -> 50100 | G10: =IF(G$4<='2. Inputs'!$E$11,'3. Dev Costs'!$F$34/'2. Inputs'!$E$11,0) -> 50100 | H10: =IF(H$4<='2. Inputs'!$E$11,'3. Dev Costs'!$F$34/'2. Inputs'!$E$11,0) -> 0 | I10: =IF(I$4<='2. Inputs'!$E$11,'3. Dev Costs'!$F$34/'2. Inputs'!$E$11,0) -> 0 | J10: =IF(J$4<='2. Inputs'!$E$11,'3. Dev Costs'!$F$34/'2. Inputs'!$E$11,0) -> 0 | K10: =IF(K$4<='2. Inputs'!$E$11,'3. Dev Costs'!$F$34/'2. Inputs'!$E$11,0) -> 0 | L10: =IF(L$4<='2. Inputs'!$E$11,'3. Dev Costs'!$F$34/'2. Inputs'!$E$11,0) -> 0 | ... AZ10: =IF(AZ$4<='2. Inputs'!$E$11,'3. Dev Costs'!$F$34/'2. Inputs'!$E$11,0) -> 0
B11: (D) Development costs | C11: =SUM(E11:AZ11) -> 2668180.4 | E11: =IF(AND(E$4>'2. Inputs'!$E$11,E$4<='2. Inputs'!$E$14),'3. Dev Costs'!$F$49/'2. Inputs'!$E$12,0) -> 0 | F11: =IF(AND(F$4>'2. Inputs'!$E$11,F$4<='2. Inputs'!$E$14),'3. Dev Costs'!$F$49/'2. Inputs'!$E$12,0) -> 0 | G11: =IF(AND(G$4>'2. Inputs'!$E$11,G$4<='2. Inputs'!$E$14),'3. Dev Costs'!$F$49/'2. Inputs'!$E$12,0) -> 0 | H11: =IF(AND(H$4>'2. Inputs'!$E$11,H$4<='2. Inputs'!$E$14),'3. Dev Costs'!$F$49/'2. Inputs'!$E$12,0) -> 222348.37 | I11: =IF(AND(I$4>'2. Inputs'!$E$11,I$4<='2. Inputs'!$E$14),'3. Dev Costs'!$F$49/'2. Inputs'!$E$12,0) -> 222348.37 | J11: =IF(AND(J$4>'2. Inputs'!$E$11,J$4<='2. Inputs'!$E$14),'3. Dev Costs'!$F$49/'2. Inputs'!$E$12,0) -> 222348.37 | K11: =IF(AND(K$4>'2. Inputs'!$E$11,K$4<='2. Inputs'!$E$14),'3. Dev Costs'!$F$49/'2. Inputs'!$E$12,0) -> 222348.37 | L11: =IF(AND(L$4>'2. Inputs'!$E$11,L$4<='2. Inputs'!$E$14),'3. Dev Costs'!$F$49/'2. Inputs'!$E$12,0) -> 222348.37 | ... AZ11: =IF(AND(AZ$4>'2. Inputs'!$E$11,AZ$4<='2. Inputs'!$E$14),'3. Dev Costs'!$F$49/'2. Inputs'!$E$12,0) -> 0
B12: (E) During construction | C12: =SUM(E12:AZ12) -> 38400 | E12: =IF(AND(E$4>'2. Inputs'!$E$11,E$4<='2. Inputs'!$E$14),'3. Dev Costs'!$F$58/'2. Inputs'!$E$12,0) -> 0 | F12: =IF(AND(F$4>'2. Inputs'!$E$11,F$4<='2. Inputs'!$E$14),'3. Dev Costs'!$F$58/'2. Inputs'!$E$12,0) -> 0 | G12: =IF(AND(G$4>'2. Inputs'!$E$11,G$4<='2. Inputs'!$E$14),'3. Dev Costs'!$F$58/'2. Inputs'!$E$12,0) -> 0 | H12: =IF(AND(H$4>'2. Inputs'!$E$11,H$4<='2. Inputs'!$E$14),'3. Dev Costs'!$F$58/'2. Inputs'!$E$12,0) -> 3200 | I12: =IF(AND(I$4>'2. Inputs'!$E$11,I$4<='2. Inputs'!$E$14),'3. Dev Costs'!$F$58/'2. Inputs'!$E$12,0) -> 3200 | J12: =IF(AND(J$4>'2. Inputs'!$E$11,J$4<='2. Inputs'!$E$14),'3. Dev Costs'!$F$58/'2. Inputs'!$E$12,0) -> 3200 | K12: =IF(AND(K$4>'2. Inputs'!$E$11,K$4<='2. Inputs'!$E$14),'3. Dev Costs'!$F$58/'2. Inputs'!$E$12,0) -> 3200 | L12: =IF(AND(L$4>'2. Inputs'!$E$11,L$4<='2. Inputs'!$E$14),'3. Dev Costs'!$F$58/'2. Inputs'!$E$12,0) -> 3200 | ... AZ12: =IF(AND(AZ$4>'2. Inputs'!$E$11,AZ$4<='2. Inputs'!$E$14),'3. Dev Costs'!$F$58/'2. Inputs'!$E$12,0) -> 0
B13: (F) Post construction | C13: =SUM(E13:AZ13) -> 13550 | E13: =IF(E$4='2. Inputs'!$E$14,'3. Dev Costs'!$F$65,0) -> 0 | F13: =IF(F$4='2. Inputs'!$E$14,'3. Dev Costs'!$F$65,0) -> 0 | G13: =IF(G$4='2. Inputs'!$E$14,'3. Dev Costs'!$F$65,0) -> 0 | H13: =IF(H$4='2. Inputs'!$E$14,'3. Dev Costs'!$F$65,0) -> 0 | I13: =IF(I$4='2. Inputs'!$E$14,'3. Dev Costs'!$F$65,0) -> 0 | J13: =IF(J$4='2. Inputs'!$E$14,'3. Dev Costs'!$F$65,0) -> 0 | K13: =IF(K$4='2. Inputs'!$E$14,'3. Dev Costs'!$F$65,0) -> 0 | L13: =IF(L$4='2. Inputs'!$E$14,'3. Dev Costs'!$F$65,0) -> 0 | ... AZ13: =IF(AZ$4='2. Inputs'!$E$14,'3. Dev Costs'!$F$65,0) -> 0
B14: (G) Sales & marketing | C14: =SUM(E14:AZ14) -> 143723.43 | E14: =IF(E$4='2. Inputs'!$E$14,'3. Dev Costs'!$F$74,0) -> 0 | F14: =IF(F$4='2. Inputs'!$E$14,'3. Dev Costs'!$F$74,0) -> 0 | G14: =IF(G$4='2. Inputs'!$E$14,'3. Dev Costs'!$F$74,0) -> 0 | H14: =IF(H$4='2. Inputs'!$E$14,'3. Dev Costs'!$F$74,0) -> 0 | I14: =IF(I$4='2. Inputs'!$E$14,'3. Dev Costs'!$F$74,0) -> 0 | J14: =IF(J$4='2. Inputs'!$E$14,'3. Dev Costs'!$F$74,0) -> 0 | K14: =IF(K$4='2. Inputs'!$E$14,'3. Dev Costs'!$F$74,0) -> 0 | L14: =IF(L$4='2. Inputs'!$E$14,'3. Dev Costs'!$F$74,0) -> 0 | ... AZ14: =IF(AZ$4='2. Inputs'!$E$14,'3. Dev Costs'!$F$74,0) -> 0
B15: (H) Other | C15: =SUM(E15:AZ15) -> 20660 | E15: =IF(E$4<='2. Inputs'!$E$14,'3. Dev Costs'!$F$85/'2. Inputs'!$E$14,0) -> 1377.3333 | F15: =IF(F$4<='2. Inputs'!$E$14,'3. Dev Costs'!$F$85/'2. Inputs'!$E$14,0) -> 1377.3333 | G15: =IF(G$4<='2. Inputs'!$E$14,'3. Dev Costs'!$F$85/'2. Inputs'!$E$14,0) -> 1377.3333 | H15: =IF(H$4<='2. Inputs'!$E$14,'3. Dev Costs'!$F$85/'2. Inputs'!$E$14,0) -> 1377.3333 | I15: =IF(I$4<='2. Inputs'!$E$14,'3. Dev Costs'!$F$85/'2. Inputs'!$E$14,0) -> 1377.3333 | J15: =IF(J$4<='2. Inputs'!$E$14,'3. Dev Costs'!$F$85/'2. Inputs'!$E$14,0) -> 1377.3333 | K15: =IF(K$4<='2. Inputs'!$E$14,'3. Dev Costs'!$F$85/'2. Inputs'!$E$14,0) -> 1377.3333 | L15: =IF(L$4<='2. Inputs'!$E$14,'3. Dev Costs'!$F$85/'2. Inputs'!$E$14,0) -> 1377.3333 | ... AZ15: =IF(AZ$4<='2. Inputs'!$E$14,'3. Dev Costs'!$F$85/'2. Inputs'!$E$14,0) -> 0
B16: TOTAL COSTS | C16: =SUM(E16:AZ16) -> 5116063.9 | E16: =SUM(E8:E15) -> 2067102.3 | F16: =SUM(F8:F15) -> 117102.33 | G16: =SUM(G8:G15) -> 51477.333 | H16: =SUM(H8:H15) -> 226925.7 | I16: =SUM(I8:I15) -> 226925.7 | J16: =SUM(J8:J15) -> 226925.7 | K16: =SUM(K8:K15) -> 226925.7 | L16: =SUM(L8:L15) -> 226925.7 | ... AZ16: =SUM(AZ8:AZ15) -> 0
B17: Cumulative costs | E17: =0+E16 -> 2067102.3 | F17: =E17+F16 -> 2184204.7 | G17: =F17+G16 -> 2235682 | H17: =G17+H16 -> 2462607.7 | I17: =H17+I16 -> 2689533.4 | J17: =I17+J16 -> 2916459.1 | K17: =J17+K16 -> 3143384.8 | L17: =K17+L16 -> 3370310.5 | M17: =L17+M16 -> 3597236.2 | ... AZ17: =AY17+AZ16 -> 5116063.9
B19: FUNDING bridge → equity → development loan
B20: Bridge advance | E20: =IF(E$4=1,'2. Inputs'!$E$21,0) -> 1267500 | F20: =IF(F$4=1,'2. Inputs'!$E$21,0) -> 0 | G20: =IF(G$4=1,'2. Inputs'!$E$21,0) -> 0 | H20: =IF(H$4=1,'2. Inputs'!$E$21,0) -> 0 | I20: =IF(I$4=1,'2. Inputs'!$E$21,0) -> 0 | J20: =IF(J$4=1,'2. Inputs'!$E$21,0) -> 0 | K20: =IF(K$4=1,'2. Inputs'!$E$21,0) -> 0 | L20: =IF(L$4=1,'2. Inputs'!$E$21,0) -> 0 | ... AZ20: =IF(AZ$4=1,'2. Inputs'!$E$21,0) -> 0
B21: Bridge interest (rolled) | E21: ='2. Inputs'!$E$21*(1+'2. Inputs'!$E$19)*'2. Inputs'!$E$18/12 -> 10773.75 | F21: =IF(F$4<='2. Inputs'!$E$11,E22*'2. Inputs'!$E$18/12,0) -> 10863.531 | G21: =IF(G$4<='2. Inputs'!$E$11,F22*'2. Inputs'!$E$18/12,0) -> 10954.061 | H21: =IF(H$4<='2. Inputs'!$E$11,G22*'2. Inputs'!$E$18/12,0) -> 0 | I21: =IF(I$4<='2. Inputs'!$E$11,H22*'2. Inputs'!$E$18/12,0) -> 0 | J21: =IF(J$4<='2. Inputs'!$E$11,I22*'2. Inputs'!$E$18/12,0) -> 0 | K21: =IF(K$4<='2. Inputs'!$E$11,J22*'2. Inputs'!$E$18/12,0) -> 0 | L21: =IF(L$4<='2. Inputs'!$E$11,K22*'2. Inputs'!$E$18/12,0) -> 0 | M21: =IF(M$4<='2. Inputs'!$E$11,L22*'2. Inputs'!$E$18/12,0) -> 0 | ... AZ21: =IF(AZ$4<='2. Inputs'!$E$11,AY22*'2. Inputs'!$E$18/12,0) -> 0
B22: Bridge balance (c/f) | E22: ='2. Inputs'!$E$21*(1+'2. Inputs'!$E$19)+E21 -> 1303623.8 | F22: =IF(F$4<='2. Inputs'!$E$11,E22+F21,0) -> 1314487.3 | G22: =IF(G$4<='2. Inputs'!$E$11,F22+G21,0) -> 1325441.3 | H22: =IF(H$4<='2. Inputs'!$E$11,G22+H21,0) -> 0 | I22: =IF(I$4<='2. Inputs'!$E$11,H22+I21,0) -> 0 | J22: =IF(J$4<='2. Inputs'!$E$11,I22+J21,0) -> 0 | K22: =IF(K$4<='2. Inputs'!$E$11,J22+K21,0) -> 0 | L22: =IF(L$4<='2. Inputs'!$E$11,K22+L21,0) -> 0 | M22: =IF(M$4<='2. Inputs'!$E$11,L22+M21,0) -> 0 | ... AZ22: =IF(AZ$4<='2. Inputs'!$E$11,AY22+AZ21,0) -> 0
B23: Bridge redemption (by dev loan) | E23: =0 -> 0 | F23: =IF(F$4='2. Inputs'!$E$13,E22*(1+'2. Inputs'!$E$20),0) -> 0 | G23: =IF(G$4='2. Inputs'!$E$13,F22*(1+'2. Inputs'!$E$20),0) -> 0 | H23: =IF(H$4='2. Inputs'!$E$13,G22*(1+'2. Inputs'!$E$20),0) -> 1338695.8 | I23: =IF(I$4='2. Inputs'!$E$13,H22*(1+'2. Inputs'!$E$20),0) -> 0 | J23: =IF(J$4='2. Inputs'!$E$13,I22*(1+'2. Inputs'!$E$20),0) -> 0 | K23: =IF(K$4='2. Inputs'!$E$13,J22*(1+'2. Inputs'!$E$20),0) -> 0 | L23: =IF(L$4='2. Inputs'!$E$13,K22*(1+'2. Inputs'!$E$20),0) -> 0 | M23: =IF(M$4='2. Inputs'!$E$13,L22*(1+'2. Inputs'!$E$20),0) -> 0 | ... AZ23: =IF(AZ$4='2. Inputs'!$E$13,AY22*(1+'2. Inputs'!$E$20),0) -> 0
B24: Equity deployed (cumulative) | E24: =MIN('2. Inputs'!$E$33,MAX(0,E17-'2. Inputs'!$E$21)) -> 799602.33 | F24: =MIN('2. Inputs'!$E$33,MAX(0,F17-'2. Inputs'!$E$21)) -> 916704.67 | G24: =MIN('2. Inputs'!$E$33,MAX(0,G17-'2. Inputs'!$E$21)) -> 968182 | H24: =MIN('2. Inputs'!$E$33,MAX(0,H17-'2. Inputs'!$E$21)) -> 1195107.7 | I24: =MIN('2. Inputs'!$E$33,MAX(0,I17-'2. Inputs'!$E$21)) -> 1400000 | J24: =MIN('2. Inputs'!$E$33,MAX(0,J17-'2. Inputs'!$E$21)) -> 1400000 | K24: =MIN('2. Inputs'!$E$33,MAX(0,K17-'2. Inputs'!$E$21)) -> 1400000 | L24: =MIN('2. Inputs'!$E$33,MAX(0,L17-'2. Inputs'!$E$21)) -> 1400000 | ... AZ24: =MIN('2. Inputs'!$E$33,MAX(0,AZ17-'2. Inputs'!$E$21)) -> 1400000
B25: Equity deployed (month) | E25: =E24-0 -> 799602.33 | F25: =F24-E24 -> 117102.33 | G25: =G24-F24 -> 51477.333 | H25: =H24-G24 -> 226925.7 | I25: =I24-H24 -> 204892.3 | J25: =J24-I24 -> 0 | K25: =K24-J24 -> 0 | L25: =L24-K24 -> 0 | M25: =M24-L24 -> 0 | ... AZ25: =AZ24-AY24 -> 0
B26: Dev loan drawdown | E26: =IF(E$4>='2. Inputs'!$E$13,MAX(0,E16-E25)+IF(E$4='2. Inputs'!$E$13,E23+'2. Inputs'!$E$30,0),0) -> 0 | F26: =IF(F$4>='2. Inputs'!$E$13,MAX(0,F16-F25)+IF(F$4='2. Inputs'!$E$13,F23+'2. Inputs'!$E$30,0),0) -> 0 | G26: =IF(G$4>='2. Inputs'!$E$13,MAX(0,G16-G25)+IF(G$4='2. Inputs'!$E$13,G23+'2. Inputs'!$E$30,0),0) -> 0 | H26: =IF(H$4>='2. Inputs'!$E$13,MAX(0,H16-H25)+IF(H$4='2. Inputs'!$E$13,H23+'2. Inputs'!$E$30,0),0) -> 1395504.6 | I26: =IF(I$4>='2. Inputs'!$E$13,MAX(0,I16-I25)+IF(I$4='2. Inputs'!$E$13,I23+'2. Inputs'!$E$30,0),0) -> 22033.406 | J26: =IF(J$4>='2. Inputs'!$E$13,MAX(0,J16-J25)+IF(J$4='2. Inputs'!$E$13,J23+'2. Inputs'!$E$30,0),0) -> 226925.7 | K26: =IF(K$4>='2. Inputs'!$E$13,MAX(0,K16-K25)+IF(K$4='2. Inputs'!$E$13,K23+'2. Inputs'!$E$30,0),0) -> 226925.7 | L26: =IF(L$4>='2. Inputs'!$E$13,MAX(0,L16-L25)+IF(L$4='2. Inputs'!$E$13,L23+'2. Inputs'!$E$30,0),0) -> 226925.7 | ... AZ26: =IF(AZ$4>='2. Inputs'!$E$13,MAX(0,AZ16-AZ25)+IF(AZ$4='2. Inputs'!$E$13,AZ23+'2. Inputs'!$E$30,0),0) -> 0
B27: Dev loan interest (rolled) | E27: =0 -> 0 | F27: =IF(F$4<='2. Inputs'!$E$14,E28*'2. Inputs'!$E$25/12,0) -> 0 | G27: =IF(G$4<='2. Inputs'!$E$14,F28*'2. Inputs'!$E$25/12,0) -> 0 | H27: =IF(H$4<='2. Inputs'!$E$14,G28*'2. Inputs'!$E$25/12,0) -> 0 | I27: =IF(I$4<='2. Inputs'!$E$14,H28*'2. Inputs'!$E$25/12,0) -> 9884.8246 | J27: =IF(J$4<='2. Inputs'!$E$14,I28*'2. Inputs'!$E$25/12,0) -> 10110.912 | K27: =IF(K$4<='2. Inputs'!$E$14,J28*'2. Inputs'!$E$25/12,0) -> 11789.921 | L27: =IF(L$4<='2. Inputs'!$E$14,K28*'2. Inputs'!$E$25/12,0) -> 13480.824 | M27: =IF(M$4<='2. Inputs'!$E$14,L28*'2. Inputs'!$E$25/12,0) -> 15183.703 | ... AZ27: =IF(AZ$4<='2. Inputs'!$E$14,AY28*'2. Inputs'!$E$25/12,0) -> 0
B28: Dev loan balance (c/f) | E28: =E26 -> 0 | F28: =IF(F$4>'2. Inputs'!$E$14,0,E28+F27+F26) -> 0 | G28: =IF(G$4>'2. Inputs'!$E$14,0,F28+G27+G26) -> 0 | H28: =IF(H$4>'2. Inputs'!$E$14,0,G28+H27+H26) -> 1395504.6 | I28: =IF(I$4>'2. Inputs'!$E$14,0,H28+I27+I26) -> 1427422.9 | J28: =IF(J$4>'2. Inputs'!$E$14,0,I28+J27+J26) -> 1664459.5 | K28: =IF(K$4>'2. Inputs'!$E$14,0,J28+K27+K26) -> 1903175.1 | L28: =IF(L$4>'2. Inputs'!$E$14,0,K28+L27+L26) -> 2143581.6 | M28: =IF(M$4>'2. Inputs'!$E$14,0,L28+M27+M26) -> 2385691.1 | ... AZ28: =IF(AZ$4>'2. Inputs'!$E$14,0,AY28+AZ27+AZ26) -> 0
B29: Funding check (pre dev-loan) | E29: =IF(AND(E$4<'2. Inputs'!$E$13,E17>'2. Inputs'!$E$21+'2. Inputs'!$E$33),"GAP","ok") -> ok | F29: =IF(AND(F$4<'2. Inputs'!$E$13,F17>'2. Inputs'!$E$21+'2. Inputs'!$E$33),"GAP","ok") -> ok | G29: =IF(AND(G$4<'2. Inputs'!$E$13,G17>'2. Inputs'!$E$21+'2. Inputs'!$E$33),"GAP","ok") -> ok | H29: =IF(AND(H$4<'2. Inputs'!$E$13,H17>'2. Inputs'!$E$21+'2. Inputs'!$E$33),"GAP","ok") -> ok | I29: =IF(AND(I$4<'2. Inputs'!$E$13,I17>'2. Inputs'!$E$21+'2. Inputs'!$E$33),"GAP","ok") -> ok | J29: =IF(AND(J$4<'2. Inputs'!$E$13,J17>'2. Inputs'!$E$21+'2. Inputs'!$E$33),"GAP","ok") -> ok | K29: =IF(AND(K$4<'2. Inputs'!$E$13,K17>'2. Inputs'!$E$21+'2. Inputs'!$E$33),"GAP","ok") -> ok | L29: =IF(AND(L$4<'2. Inputs'!$E$13,L17>'2. Inputs'!$E$21+'2. Inputs'!$E$33),"GAP","ok") -> ok | ... AZ29: =IF(AND(AZ$4<'2. Inputs'!$E$13,AZ17>'2. Inputs'!$E$21+'2. Inputs'!$E$33),"GAP","ok") -> ok
B31: FINANCE SUMMARY
B32: Bridge arrangement fee | C32: ='2. Inputs'!E21*'2. Inputs'!E19 -> 25350
B33: Bridge interest (total) | C33: =SUM(E21:AZ21) -> 32591.342
B34: Bridge exit fee | C34: =INDEX(E22:AZ22,'2. Inputs'!E11)*'2. Inputs'!E20 -> 13254.413
B35: Bridge redemption (total) | C35: =SUM(E23:AZ23) -> 1338695.8
B36: Dev loan arrangement fee | C36: ='2. Inputs'!E30 -> 56808.894
B37: Dev loan interest (total to PC) | C37: =SUM(E27:AZ27) -> 187994.37
B38: Dev loan balance at PC | C38: =INDEX(E28:AZ28,'2. Inputs'!E14) -> 4032062.9
B39: Dev loan exit fee | C39: =C38*'2. Inputs'!E27 -> 40320.629
B40: Dev loan payoff at PC (balance + exit fee) | C40: =C38+C39 -> 4072383.5
B41: Peak dev loan balance | C41: =MAX(E28:AZ28) -> 4032062.9
B42: LTGDV at peak | C42: =IF('1. Unit Import'!F42=0,0,C41/'1. Unit Import'!F42) -> 0.64531295 | D42: =IF(C42<='2. Inputs'!E28,"ok","OVER COVENANT") -> ok
B43: TOTAL FINANCE COSTS | C43: =C32+C33+C34+C36+C37+C39 -> 356319.64
B44: TOTAL COSTS AFTER FINANCE | C44: ='3. Dev Costs'!F87+C43 -> 5472383.5
...

Sheet 5. Scenarios
B2: 5. Scenario Analysis Post Development Exit Options
B4: SCENARIO 1 — IMMEDIATE SALE AT PRACTICAL COMPLETION (all units at GDV)
C5: GDV (adjusted for price lever) | F5: ='1. Unit Import'!F42*(1+'2. Inputs'!E43) -> 6248228.7
C6: Total costs pre-finance | F6: ='3. Dev Costs'!F87 -> 5116063.9
C7: Total finance costs | F7: ='4. Cashflow'!C43 -> 356319.64
C8: Total costs after finance | F8: ='4. Cashflow'!C44 -> 5472383.5
C9: NET PROFIT | F9: =F5-F8 -> 775845.16
C10: Profit on cost | F10: =IF(F8=0,0,F9/F8) -> 0.14177463
C11: Profit on GDV | F11: =IF(F5=0,0,F9/F5) -> 0.12417042
C12: Dev loan payoff at PC | F12: ='4. Cashflow'!C40 -> 4072383.5
C13: Investor profit share | F13: =F9*'2. Inputs'!E34 -> 387922.58
C14: Developer profit share | F14: =F9*'2. Inputs'!E35 -> 387922.58
C15: Investor ROI (on investor equity) | F15: =IF('2. Inputs'!E36=0,0,F13/'2. Inputs'!E36) -> 0.55417512
C16: Project duration (months) | F16: ='2. Inputs'!E14 -> 15
C17: Investor ROI per annum | F17: =IF(F16=0,0,F15*12/F16) -> 0.44334009
B20: SCENARIO 2 — DELAYED SALES (dev loan keeps rolling until repaid from unit sales)
B21: Units sell at the velocity input at average unit price (GDV ÷ units). Net proceeds repay the loan; interest rolls on the outstanding balance.
B23: Month after PC | E23: 1 | F23: 2 | G23: 3 | H23: 4 | I23: 5 | J23: 6 | K23: 7 | L23: 8 | M23: 9 | N23: 10 | O23: 11 | P23: 12 | Q23: 13 | R23: 14 | S23: 15 | T23: 16 | U23: 17 | V23: 18 | W23: 19 | X23: 20 | Y23: 21 | Z23: 22 | AA23: 23 | AB23: 24 | AC23: 25 | AD23: 26 | AE23: 27 | AF23: 28 | AG23: 29 | AH23: 30 | AI23: 31 | AJ23: 32 | AK23: 33 | AL23: 34 | AM23: 35 | AN23: 36
B24: Units sold | E24: =MIN('2. Inputs'!$E$42,'1. Unit Import'!$F$40) -> 2 | F24: =MIN('2. Inputs'!$E$42,E25) -> 2 | G24: =MIN('2. Inputs'!$E$42,F25) -> 2 | H24: =MIN('2. Inputs'!$E$42,G25) -> 2 | I24: =MIN('2. Inputs'!$E$42,H25) -> 2 | J24: =MIN('2. Inputs'!$E$42,I25) -> 2 | K24: =MIN('2. Inputs'!$E$42,J25) -> 0 | L24: =MIN('2. Inputs'!$E$42,K25) -> 0 | M24: =MIN('2. Inputs'!$E$42,L25) -> 0 | ... AN24: =MIN('2. Inputs'!$E$42,AM25) -> 0
B25: Units remaining (c/f) | E25: ='1. Unit Import'!$F$40-E24 -> 10 | F25: =E25-F24 -> 8 | G25: =F25-G24 -> 6 | H25: =G25-H24 -> 4 | I25: =H25-I24 -> 2 | J25: =I25-J24 -> 0 | K25: =J25-K24 -> 0 | L25: =K25-L24 -> 0 | M25: =L25-M24 -> 0 | ... AN25: =AM25-AN24 -> 0
B26: Gross sale proceeds | E26: =E24*IF('1. Unit Import'!$F$40=0,0,$F$5/'1. Unit Import'!$F$40) -> 1041371.4 | F26: =F24*IF('1. Unit Import'!$F$40=0,0,$F$5/'1. Unit Import'!$F$40) -> 1041371.4 | G26: =G24*IF('1. Unit Import'!$F$40=0,0,$F$5/'1. Unit Import'!$F$40) -> 1041371.4 | H26: =H24*IF('1. Unit Import'!$F$40=0,0,$F$5/'1. Unit Import'!$F$40) -> 1041371.4 | I26: =I24*IF('1. Unit Import'!$F$40=0,0,$F$5/'1. Unit Import'!$F$40) -> 1041371.4 | J26: =J24*IF('1. Unit Import'!$F$40=0,0,$F$5/'1. Unit Import'!$F$40) -> 1041371.4 | K26: =K24*IF('1. Unit Import'!$F$40=0,0,$F$5/'1. Unit Import'!$F$40) -> 0 | L26: =L24*IF('1. Unit Import'!$F$40=0,0,$F$5/'1. Unit Import'!$F$40) -> 0 | ... AN26: =AN24*IF('1. Unit Import'!$F$40=0,0,$F$5/'1. Unit Import'!$F$40) -> 0
B27: Net proceeds (after fees & legals) | E27: =E26*(1-'2. Inputs'!$E$40)-E24*'2. Inputs'!$E$41 -> 1024250.9 | F27: =F26*(1-'2. Inputs'!$E$40)-F24*'2. Inputs'!$E$41 -> 1024250.9 | G27: =G26*(1-'2. Inputs'!$E$40)-G24*'2. Inputs'!$E$41 -> 1024250.9 | H27: =H26*(1-'2. Inputs'!$E$40)-H24*'2. Inputs'!$E$41 -> 1024250.9 | I27: =I26*(1-'2. Inputs'!$E$40)-I24*'2. Inputs'!$E$41 -> 1024250.9 | J27: =J26*(1-'2. Inputs'!$E$40)-J24*'2. Inputs'!$E$41 -> 1024250.9 | K27: =K26*(1-'2. Inputs'!$E$40)-K24*'2. Inputs'!$E$41 -> 0 | L27: =L26*(1-'2. Inputs'!$E$40)-L24*'2. Inputs'!$E$41 -> 0 | ... AN27: =AN26*(1-'2. Inputs'!$E$40)-AN24*'2. Inputs'!$E$41 -> 0
B28: Loan opening | E28: ='4. Cashflow'!$C$40 -> 4072383.5 | F28: =E31 -> 3076978.7 | G28: =F31 -> 2074523.1 | H28: =G31 -> 1064966.7 | I28: =H31 -> 48259.384 | J28: =I31 -> 0 | K28: =J31 -> 0 | L28: =K31 -> 0 | M28: =L31 -> 0 | ... AN28: =AM31 -> 0
B29: Interest (rolled) | E29: =E28*'2. Inputs'!$E$25/12 -> 28846.05 | F29: =F28*'2. Inputs'!$E$25/12 -> 21795.266 | G29: =G28*'2. Inputs'!$E$25/12 -> 14694.538 | H29: =H28*'2. Inputs'!$E$25/12 -> 7543.5144 | I29: =I28*'2. Inputs'!$E$25/12 -> 341.8373 | J29: =J28*'2. Inputs'!$E$25/12 -> 0 | K29: =K28*'2. Inputs'!$E$25/12 -> 0 | L29: =L28*'2. Inputs'!$E$25/12 -> 0 | ... AN29: =AN28*'2. Inputs'!$E$25/12 -> 0
B30: Repayment | E30: =MIN(E28+E29,MAX(0,E27)) -> 1024250.9 | F30: =MIN(F28+F29,MAX(0,F27)) -> 1024250.9 | G30: =MIN(G28+G29,MAX(0,G27)) -> 1024250.9 | H30: =MIN(H28+H29,MAX(0,H27)) -> 1024250.9 | I30: =MIN(I28+I29,MAX(0,I27)) -> 48601.221 | J30: =MIN(J28+J29,MAX(0,J27)) -> 0 | K30: =MIN(K28+K29,MAX(0,K27)) -> 0 | L30: =MIN(L28+L29,MAX(0,L27)) -> 0 | ... AN30: =MIN(AN28+AN29,MAX(0,AN27)) -> 0
B31: Loan closing | E31: =E28+E29-E30 -> 3076978.7 | F31: =F28+F29-F30 -> 2074523.1 | G31: =G28+G29-G30 -> 1064966.7 | H31: =H28+H29-H30 -> 48259.384 | I31: =I28+I29-I30 -> 0 | J31: =J28+J29-J30 -> 0 | K31: =K28+K29-K30 -> 0 | L31: =L28+L29-L30 -> 0 | ... AN31: =AN28+AN29-AN30 -> 0
C33: Months to sell out | F33: =IF('2. Inputs'!E42=0,0,ROUNDUP('1. Unit Import'!F40/'2. Inputs'!E42,0)) -> 6
C34: Months until loan repaid | F34: =IF(INDEX(E31:AN31,36)>0.01,"36+",COUNTIF(E31:AN31,">0.01")+1) -> 5
C35: Extra interest after PC | F35: =SUM(E29:AN29) -> 73221.206
C36: NET PROFIT (Scenario 2) | F36: =F9-F35 -> 702623.96
C37: Investor profit share | F37: =F36*'2. Inputs'!E34 -> 351311.98
C38: Investor ROI | F38: =IF('2. Inputs'!E36=0,0,F37/'2. Inputs'!E36) -> 0.50187425
C39: Total duration (months) | F39: =F16+F33 -> 21
B42: SCENARIO 3 — REFINANCE AT PC & RENT (exit bridge / commercial mortgage, hold as PRS)
C43: Mortgage advance (LTV × GDV) | F43: ='2. Inputs'!E46*F5 -> 4061348.6
C44: Arrangement fee | F44: =F43*'2. Inputs'!E48 -> 40613.486
C45: Dev loan payoff | F45: =F12 -> 4072383.5
C46: Surplus released / (equity gap) | F46: =F43-F44-F45 -> -51648.359
C47: Gross annual rent | F47: ='1. Unit Import'!F46 -> 240000
C48: Net annual rent (after void & mgmt) | F48: =F47*(1-'2. Inputs'!E49)*(1-'2. Inputs'!E50) -> 193800
...

Sheet 6. Sensitivity
B2: 6. Sensitivity Analysis
B4: Fixed cost base (all costs after finance, excl. price-dependent selling costs) | F4: ='4. Cashflow'!C44-'3. Dev Costs'!F70-'3. Dev Costs'!F71 -> 5369660.1
B6: GRID 1 — Scenario 1 net profit vs sale price movement (exact)
B7: Price vs GDV | C7: Net profit | D7: Profit on GDV
B8: -0.1 | C8: ='1. Unit Import'!$F$42*(1+B8)*(1-'2. Inputs'!$E$40)-'2. Inputs'!$E$41*'1. Unit Import'!$F$40-$F$4 -> 160394.64 | D8: =IF('1. Unit Import'!$F$42=0,0,C8/('1. Unit Import'!$F$42*(1+B8))) -> 0.028522686
B9: -0.05 | C9: ='1. Unit Import'!$F$42*(1+B9)*(1-'2. Inputs'!$E$40)-'2. Inputs'!$E$41*'1. Unit Import'!$F$40-$F$4 -> 468119.9 | D9: =IF('1. Unit Import'!$F$42=0,0,C9/('1. Unit Import'!$F$42*(1+B9))) -> 0.078863597
B10: 0 | C10: ='1. Unit Import'!$F$42*(1+B10)*(1-'2. Inputs'!$E$40)-'2. Inputs'!$E$41*'1. Unit Import'!$F$40-$F$4 -> 775845.16 | D10: =IF('1. Unit Import'!$F$42=0,0,C10/('1. Unit Import'!$F$42*(1+B10))) -> 0.12417042
B11: 0.05 | C11: ='1. Unit Import'!$F$42*(1+B11)*(1-'2. Inputs'!$E$40)-'2. Inputs'!$E$41*'1. Unit Import'!$F$40-$F$4 -> 1083570.4 | D11: =IF('1. Unit Import'!$F$42=0,0,C11/('1. Unit Import'!$F$42*(1+B11))) -> 0.1651623
B12: 0.1 | C12: ='1. Unit Import'!$F$42*(1+B12)*(1-'2. Inputs'!$E$40)-'2. Inputs'!$E$41*'1. Unit Import'!$F$40-$F$4 -> 1391295.7 | D12: =IF('1. Unit Import'!$F$42=0,0,C12/('1. Unit Import'!$F$42*(1+B12))) -> 0.20242765
B15: GRID 2 — Scenario 2 net profit: price movement × sales velocity (approximation*)
B16: Price \ Units/mo | C16: 1 | D16: 2 | E16: 3 | F16: 4 | G16: 6
B17: =B8 -> -0.1 | C17: =$C$8-'4. Cashflow'!$C$40*('2. Inputs'!$E$25/12)*(MIN(ROUNDUP('1. Unit Import'!$F$40/C$16,0),ROUNDUP('4. Cashflow'!$C$40/MAX(1,(C$16*('1. Unit Import'!$F$42*(1+$B17)/'1. Unit Import'!$F$40)*(1-'2. Inputs'!$E$40)-C$16*'2. Inputs'!$E$41)),0))+1)/2 -> 16164.389 | D17: =$C$8-'4. Cashflow'!$C$40*('2. Inputs'!$E$25/12)*(MIN(ROUNDUP('1. Unit Import'!$F$40/D$16,0),ROUNDUP('4. Cashflow'!$C$40/MAX(1,(D$16*('1. Unit Import'!$F$42*(1+$B17)/'1. Unit Import'!$F$40)*(1-'2. Inputs'!$E$40)-D$16*'2. Inputs'!$E$41)),0))+1)/2 -> 73856.488 | E17: =$C$8-'4. Cashflow'!$C$40*('2. Inputs'!$E$25/12)*(MIN(ROUNDUP('1. Unit Import'!$F$40/E$16,0),ROUNDUP('4. Cashflow'!$C$40/MAX(1,(E$16*('1. Unit Import'!$F$42*(1+$B17)/'1. Unit Import'!$F$40)*(1-'2. Inputs'!$E$40)-E$16*'2. Inputs'!$E$41)),0))+1)/2 -> 102702.54 | F17: =$C$8-'4. Cashflow'!$C$40*('2. Inputs'!$E$25/12)*(MIN(ROUNDUP('1. Unit Import'!$F$40/F$16,0),ROUNDUP('4. Cashflow'!$C$40/MAX(1,(F$16*('1. Unit Import'!$F$42*(1+$B17)/'1. Unit Import'!$F$40)*(1-'2. Inputs'!$E$40)-F$16*'2. Inputs'!$E$41)),0))+1)/2 -> 102702.54 | G17: =$C$8-'4. Cashflow'!$C$40*('2. Inputs'!$E$25/12)*(MIN(ROUNDUP('1. Unit Import'!$F$40/G$16,0),ROUNDUP('4. Cashflow'!$C$40/MAX(1,(G$16*('1. Unit Import'!$F$42*(1+$B17)/'1. Unit Import'!$F$40)*(1-'2. Inputs'!$E$40)-G$16*'2. Inputs'!$E$41)),0))+1)/2 -> 117125.56
B18: =B9 -> -0.05 | C18: =$C$9-'4. Cashflow'!$C$40*('2. Inputs'!$E$25/12)*(MIN(ROUNDUP('1. Unit Import'!$F$40/C$16,0),ROUNDUP('4. Cashflow'!$C$40/MAX(1,(C$16*('1. Unit Import'!$F$42*(1+$B18)/'1. Unit Import'!$F$40)*(1-'2. Inputs'!$E$40)-C$16*'2. Inputs'!$E$41)),0))+1)/2 -> 323889.65 | D18: =$C$9-'4. Cashflow'!$C$40*('2. Inputs'!$E$25/12)*(MIN(ROUNDUP('1. Unit Import'!$F$40/D$16,0),ROUNDUP('4. Cashflow'!$C$40/MAX(1,(D$16*('1. Unit Import'!$F$42*(1+$B18)/'1. Unit Import'!$F$40)*(1-'2. Inputs'!$E$40)-D$16*'2. Inputs'!$E$41)),0))+1)/2 -> 381581.75 | E18: =$C$9-'4. Cashflow'!$C$40*('2. Inputs'!$E$25/12)*(MIN(ROUNDUP('1. Unit Import'!$F$40/E$16,0),ROUNDUP('4. Cashflow'!$C$40/MAX(1,(E$16*('1. Unit Import'!$F$42*(1+$B18)/'1. Unit Import'!$F$40)*(1-'2. Inputs'!$E$40)-E$16*'2. Inputs'!$E$41)),0))+1)/2 -> 410427.8 | F18: =$C$9-'4. Cashflow'!$C$40*('2. Inputs'!$E$25/12)*(MIN(ROUNDUP('1. Unit Import'!$F$40/F$16,0),ROUNDUP('4. Cashflow'!$C$40/MAX(1,(F$16*('1. Unit Import'!$F$42*(1+$B18)/'1. Unit Import'!$F$40)*(1-'2. Inputs'!$E$40)-F$16*'2. Inputs'!$E$41)),0))+1)/2 -> 410427.8 | G18: =$C$9-'4. Cashflow'!$C$40*('2. Inputs'!$E$25/12)*(MIN(ROUNDUP('1. Unit Import'!$F$40/G$16,0),ROUNDUP('4. Cashflow'!$C$40/MAX(1,(G$16*('1. Unit Import'!$F$42*(1+$B18)/'1. Unit Import'!$F$40)*(1-'2. Inputs'!$E$40)-G$16*'2. Inputs'!$E$41)),0))+1)/2 -> 424850.83
B19: =B10 -> 0 | C19: =$C$10-'4. Cashflow'!$C$40*('2. Inputs'!$E$25/12)*(MIN(ROUNDUP('1. Unit Import'!$F$40/C$16,0),ROUNDUP('4. Cashflow'!$C$40/MAX(1,(C$16*('1. Unit Import'!$F$42*(1+$B19)/'1. Unit Import'!$F$40)*(1-'2. Inputs'!$E$40)-C$16*'2. Inputs'!$E$41)),0))+1)/2 -> 646037.94 | D19: =$C$10-'4. Cashflow'!$C$40*('2. Inputs'!$E$25/12)*(MIN(ROUNDUP('1. Unit Import'!$F$40/D$16,0),ROUNDUP('4. Cashflow'!$C$40/MAX(1,(D$16*('1. Unit Import'!$F$42*(1+$B19)/'1. Unit Import'!$F$40)*(1-'2. Inputs'!$E$40)-D$16*'2. Inputs'!$E$41)),0))+1)/2 -> 703730.04 | E19: =$C$10-'4. Cashflow'!$C$40*('2. Inputs'!$E$25/12)*(MIN(ROUNDUP('1. Unit Import'!$F$40/E$16,0),ROUNDUP('4. Cashflow'!$C$40/MAX(1,(E$16*('1. Unit Import'!$F$42*(1+$B19)/'1. Unit Import'!$F$40)*(1-'2. Inputs'!$E$40)-E$16*'2. Inputs'!$E$41)),0))+1)/2 -> 718153.06 | F19: =$C$10-'4. Cashflow'!$C$40*('2. Inputs'!$E$25/12)*(MIN(ROUNDUP('1. Unit Import'!$F$40/F$16,0),ROUNDUP('4. Cashflow'!$C$40/MAX(1,(F$16*('1. Unit Import'!$F$42*(1+$B19)/'1. Unit Import'!$F$40)*(1-'2. Inputs'!$E$40)-F$16*'2. Inputs'!$E$41)),0))+1)/2 -> 732576.09 | G19: =$C$10-'4. Cashflow'!$C$40*('2. Inputs'!$E$25/12)*(MIN(ROUNDUP('1. Unit Import'!$F$40/G$16,0),ROUNDUP('4. Cashflow'!$C$40/MAX(1,(G$16*('1. Unit Import'!$F$42*(1+$B19)/'1. Unit Import'!$F$40)*(1-'2. Inputs'!$E$40)-G$16*'2. Inputs'!$E$41)),0))+1)/2 -> 732576.09
B20: =B11 -> 0.05 | C20: =$C$11-'4. Cashflow'!$C$40*('2. Inputs'!$E$25/12)*(MIN(ROUNDUP('1. Unit Import'!$F$40/C$16,0),ROUNDUP('4. Cashflow'!$C$40/MAX(1,(C$16*('1. Unit Import'!$F$42*(1+$B20)/'1. Unit Import'!$F$40)*(1-'2. Inputs'!$E$40)-C$16*'2. Inputs'!$E$41)),0))+1)/2 -> 953763.2 | D20: =$C$11-'4. Cashflow'!$C$40*('2. Inputs'!$E$25/12)*(MIN(ROUNDUP('1. Unit Import'!$F$40/D$16,0),ROUNDUP('4. Cashflow'!$C$40/MAX(1,(D$16*('1. Unit Import'!$F$42*(1+$B20)/'1. Unit Import'!$F$40)*(1-'2. Inputs'!$E$40)-D$16*'2. Inputs'!$E$41)),0))+1)/2 -> 1011455.3 | E20: =$C$11-'4. Cashflow'!$C$40*('2. Inputs'!$E$25/12)*(MIN(ROUNDUP('1. Unit Import'!$F$40/E$16,0),ROUNDUP('4. Cashflow'!$C$40/MAX(1,(E$16*('1. Unit Import'!$F$42*(1+$B20)/'1. Unit Import'!$F$40)*(1-'2. Inputs'!$E$40)-E$16*'2. Inputs'!$E$41)),0))+1)/2 -> 1025878.3 | F20: =$C$11-'4. Cashflow'!$C$40*('2. Inputs'!$E$25/12)*(MIN(ROUNDUP('1. Unit Import'!$F$40/F$16,0),ROUNDUP('4. Cashflow'!$C$40/MAX(1,(F$16*('1. Unit Import'!$F$42*(1+$B20)/'1. Unit Import'!$F$40)*(1-'2. Inputs'!$E$40)-F$16*'2. Inputs'!$E$41)),0))+1)/2 -> 1040301.3 | G20: =$C$11-'4. Cashflow'!$C$40*('2. Inputs'!$E$25/12)*(MIN(ROUNDUP('1. Unit Import'!$F$40/G$16,0),ROUNDUP('4. Cashflow'!$C$40/MAX(1,(G$16*('1. Unit Import'!$F$42*(1+$B20)/'1. Unit Import'!$F$40)*(1-'2. Inputs'!$E$40)-G$16*'2. Inputs'!$E$41)),0))+1)/2 -> 1040301.3
B21: =B12 -> 0.1 | C21: =$C$12-'4. Cashflow'!$C$40*('2. Inputs'!$E$25/12)*(MIN(ROUNDUP('1. Unit Import'!$F$40/C$16,0),ROUNDUP('4. Cashflow'!$C$40/MAX(1,(C$16*('1. Unit Import'!$F$42*(1+$B21)/'1. Unit Import'!$F$40)*(1-'2. Inputs'!$E$40)-C$16*'2. Inputs'!$E$41)),0))+1)/2 -> 1261488.5 | D21: =$C$12-'4. Cashflow'!$C$40*('2. Inputs'!$E$25/12)*(MIN(ROUNDUP('1. Unit Import'!$F$40/D$16,0),ROUNDUP('4. Cashflow'!$C$40/MAX(1,(D$16*('1. Unit Import'!$F$42*(1+$B21)/'1. Unit Import'!$F$40)*(1-'2. Inputs'!$E$40)-D$16*'2. Inputs'!$E$41)),0))+1)/2 -> 1319180.6 | E21: =$C$12-'4. Cashflow'!$C$40*('2. Inputs'!$E$25/12)*(MIN(ROUNDUP('1. Unit Import'!$F$40/E$16,0),ROUNDUP('4. Cashflow'!$C$40/MAX(1,(E$16*('1. Unit Import'!$F$42*(1+$B21)/'1. Unit Import'!$F$40)*(1-'2. Inputs'!$E$40)-E$16*'2. Inputs'!$E$41)),0))+1)/2 -> 1333603.6 | F21: =$C$12-'4. Cashflow'!$C$40*('2. Inputs'!$E$25/12)*(MIN(ROUNDUP('1. Unit Import'!$F$40/F$16,0),ROUNDUP('4. Cashflow'!$C$40/MAX(1,(F$16*('1. Unit Import'!$F$42*(1+$B21)/'1. Unit Import'!$F$40)*(1-'2. Inputs'!$E$40)-F$16*'2. Inputs'!$E$41)),0))+1)/2 -> 1348026.6 | G21: =$C$12-'4. Cashflow'!$C$40*('2. Inputs'!$E$25/12)*(MIN(ROUNDUP('1. Unit Import'!$F$40/G$16,0),ROUNDUP('4. Cashflow'!$C$40/MAX(1,(G$16*('1. Unit Import'!$F$42*(1+$B21)/'1. Unit Import'!$F$40)*(1-'2. Inputs'!$E$40)-G$16*'2. Inputs'!$E$41)),0))+1)/2 -> 1348026.6
B23: *Approximate: assumes straight-line paydown of the dev loan; exact base case is in Scenario 2 on '5. Scenarios'.
B25: GRID 3 — Refinance & rent: net annual cashflow by refi rate × LTV (exact)
B26: Rate \ LTV | C26: 0.55 | D26: 0.6 | E26: 0.65 | F26: 0.7
B27: 0.045 | C27: ='5. Scenarios'!$F$48-'5. Scenarios'!$F$5*C$26*$B27 -> 39156.34 | D27: ='5. Scenarios'!$F$48-'5. Scenarios'!$F$5*D$26*$B27 -> 25097.826 | E27: ='5. Scenarios'!$F$48-'5. Scenarios'!$F$5*E$26*$B27 -> 11039.311 | F27: ='5. Scenarios'!$F$48-'5. Scenarios'!$F$5*F$26*$B27 -> -3019.2032
B28: 0.05 | C28: ='5. Scenarios'!$F$48-'5. Scenarios'!$F$5*C$26*$B28 -> 21973.712 | D28: ='5. Scenarios'!$F$48-'5. Scenarios'!$F$5*D$26*$B28 -> 6353.1398 | E28: ='5. Scenarios'!$F$48-'5. Scenarios'!$F$5*E$26*$B28 -> -9267.4318 | F28: ='5. Scenarios'!$F$48-'5. Scenarios'!$F$5*F$26*$B28 -> -24888.004
B29: 0.055 | C29: ='5. Scenarios'!$F$48-'5. Scenarios'!$F$5*C$26*$B29 -> 4791.0827 | D29: ='5. Scenarios'!$F$48-'5. Scenarios'!$F$5*D$26*$B29 -> -12391.546 | E29: ='5. Scenarios'!$F$48-'5. Scenarios'!$F$5*E$26*$B29 -> -29574.175 | F29: ='5. Scenarios'!$F$48-'5. Scenarios'!$F$5*F$26*$B29 -> -46756.804
B30: 0.06 | C30: ='5. Scenarios'!$F$48-'5. Scenarios'!$F$5*C$26*$B30 -> -12391.546 | D30: ='5. Scenarios'!$F$48-'5. Scenarios'!$F$5*D$26*$B30 -> -31136.232 | E30: ='5. Scenarios'!$F$48-'5. Scenarios'!$F$5*E$26*$B30 -> -49880.918 | F30: ='5. Scenarios'!$F$48-'5. Scenarios'!$F$5*F$26*$B30 -> -68625.604
B31: 0.065 | C31: ='5. Scenarios'!$F$48-'5. Scenarios'!$F$5*C$26*$B31 -> -29574.175 | D31: ='5. Scenarios'!$F$48-'5. Scenarios'!$F$5*D$26*$B31 -> -49880.918 | E31: ='5. Scenarios'!$F$48-'5. Scenarios'!$F$5*E$26*$B31 -> -70187.661 | F31: ='5. Scenarios'!$F$48-'5. Scenarios'!$F$5*F$26*$B31 -> -90494.405

Sheet Sheet1
